<?xml version="1.0"?>
<!-- This URDF was automatically created by SolidWorks to URDF Exporter! Originally created by Stephen Brawner (brawner@gmail.com) 
     Commit Version: 1.6.0-4-g7f85cfe  Build Version: 1.6.7995.38578
     For more information, please see http://wiki.ros.org/sw_urdf_exporter -->
<robot
  name="leg_model_1">
  <link
    name="base_link">
    <inertial>
      <origin
        xyz="-0.00014624 -0.0043208 0.30277"
        rpy="0 0 0" />
      <mass
        value="10502.11" />
      <inertia
        ixx="1076.39"
        ixy="0.00"
        ixz="-0.02"
        iyy="1072.16"
        iyz="-0.08"
        izz="44.67" />
    </inertial>
    <visual>
      <origin
        xyz="0 0 0"
        rpy="0 0 0" />
      <geometry>
        <mesh
          filename="file:///home/llq/leg_control/install/leg_model_1/share/leg_model_1/meshes/base_link.STL" />
      </geometry>
      <material
        name="">
        <color
          rgba="0.79216 0.81961 0.93333 1" />
      </material>
    </visual>
    <collision>
      <origin
        xyz="0 0 0"
        rpy="0 0 0" />
      <geometry>
        <mesh
          filename="file:///home/llq/leg_control/install/leg_model_1/share/leg_model_1/meshes/base_link.STL" />
      </geometry>
    </collision>
  </link>
  <link
    name="hip_link">
    <inertial>
      <origin
        xyz="-0.023835 0.00094841 0.039743"
        rpy="0 0 3.14159" />
      <mass
        value="0.52760000" />
      <inertia
        ixx="0.00036792"
        ixy="0.00000139"
        ixz="0.00003833"
        iyy="0.00040268"
        iyz="-0.00000156"
        izz="0.00034332" />
    </inertial>
    <visual>
      <origin
        xyz="0 0 0"
        rpy="0 0 3.14159" />
      <geometry>
        <mesh
          filename="file:///home/llq/leg_control/install/leg_model_1/share/leg_model_1/meshes/hip_link.STL" />
      </geometry>
      <material
        name="">
        <color
          rgba="0.79216 0.81961 0.93333 1" />
      </material>
    </visual>
    <collision>
      <origin
        xyz="0 0 0"
        rpy="0 0 0" />
      <geometry>
        <mesh
          filename="file:///home/llq/leg_control/install/leg_model_1/share/leg_model_1/meshes/hip_link.STL" />
      </geometry>
    </collision>
  </link>
  <joint
    name="hip_joint"
    type="revolute">
    <origin
      xyz="-0.00067863 -0.06 0.41107"
      rpy="1.5708 0 0" />
    <parent
      link="base_link" />
    <child
      link="hip_link" />
    <axis
      xyz="0 0 1" />
    <limit
      lower="3.13"
      upper="3.14"
      effort="20"
      velocity="20" />
  </joint>
  <link
    name="big_leg_Link">
    <inertial>
      <origin
        xyz="-0.019809 -0.01644 -0.060094"
        rpy="0 0 0" />
      <mass
        value="0.75553000" />
      <inertia
        ixx="0.00167856"
        ixy="-0.00075514"
        ixz="-0.00036372"
        iyy="0.00189370"
        iyz="0.00030137"
        izz="0.00203925" />
    </inertial>
    <visual>
      <origin
        xyz="0 0 0"
        rpy="0 0 0" />
      <geometry>
        <mesh
          filename="file:///home/llq/leg_control/install/leg_model_1/share/leg_model_1/meshes/big_leg_Link.STL" />
      </geometry>
      <material
        name="">
        <color
          rgba="0.79216 0.81961 0.93333 1" />
      </material>
    </visual>
    <collision>
      <origin
        xyz="0 0 0"
        rpy="0 0 0" />
      <geometry>
        <mesh
          filename="file:///home/llq/leg_control/install/leg_model_1/share/leg_model_1/meshes/big_leg_Link.STL" />
      </geometry>
    </collision>
  </link>
  <joint
    name="big_leg_joint"
    type="revolute">
    <origin
      xyz="0.0054956 -0.00021879 0.045"
      rpy="3.1018 -1.5708 0" />
    <parent
      link="hip_link" />
    <child
      link="big_leg_Link" />
    <axis
      xyz="0 0 1" />
    <limit
      lower="-3.14"
      upper="3.14"
      effort="20"
      velocity="20" />
  </joint>
  <link
    name="thigh_link">
    <inertial>
      <origin
        xyz="-0.0038142 -0.0047456 -0.0021178"
        rpy="0 0 0" />
      <mass
        value="0.02498000" />
      <inertia
        ixx="0.00000569"
        ixy="-0.00000262"
        ixz="0.00000132"
        iyy="0.00000453"
        iyz="0.00000165"
        izz="0.00000808" />
    </inertial>
    <visual>
      <origin
        xyz="0 0 0"
        rpy="0 0 0" />
      <geometry>
        <mesh
          filename="file:///home/llq/leg_control/install/leg_model_1/share/leg_model_1/meshes/thigh_link.STL" />
      </geometry>
      <material
        name="">
        <color
          rgba="0.79216 0.81961 0.93333 1" />
      </material>
    </visual>
    <collision>
      <origin
        xyz="0 0 0"
        rpy="0 0 0" />
      <geometry>
        <mesh
          filename="file:///home/llq/leg_control/install/leg_model_1/share/leg_model_1/meshes/thigh_link.STL" />
      </geometry>
    </collision>
  </link>
  <joint
    name="thigh_joint"
    type="revolute">
    <origin
      xyz="0 0 -0.0823"
      rpy="-3.1416 0 0" />
    <parent
      link="big_leg_Link" />
    <child
      link="thigh_link" />
    <axis
      xyz="0 0 1" />
    <limit
      lower="-0.55"
      upper="0.15"
      effort="20"
      velocity="20" />
  </joint>
  <link
    name="Rod_link">
    <inertial>
      <origin
        xyz="-0.068989 0.071266 -0.0038195"
        rpy="0 0 0" />
      <mass
        value="0.03111000" />
      <inertia
        ixx="0.00006403"
        ixy="0.00006126"
        ixz="0.00000004"
        iyy="0.00006001"
        iyz="-0.00000004"
        izz="0.00012343" />
    </inertial>
    <visual>
      <origin
        xyz="0 0 0"
        rpy="0 0 0" />
      <geometry>
        <mesh
          filename="file:///home/llq/leg_control/install/leg_model_1/share/leg_model_1/meshes/Rod_link.STL" />
      </geometry>
      <material
        name="">
        <color
          rgba="0.79216 0.81961 0.93333 1" />
      </material>
    </visual>
    <collision>
      <origin
        xyz="0 0 0"
        rpy="0 0 0" />
      <geometry>
        <mesh
          filename="file:///home/llq/leg_control/install/leg_model_1/share/leg_model_1/meshes/Rod_link.STL" />
      </geometry>
    </collision>
  </link>
  <joint
    name="Rod_joint"
    type="revolute">
    <origin
      xyz="-0.018796 -0.023382 0.0128"
      rpy="0 0 0" />
    <parent
      link="thigh_link" />
    <child
      link="Rod_link" />
    <axis
      xyz="0 0 1" />
    <limit
      lower="-3.14"
      upper="3.14"
      effort="20"
      velocity="20" />
    <mimic
      joint="thigh_joint"
      multiplier="-1"
      offset="0" />
  </joint>
  <link
    name="Knee_link">
    <inertial>
      <origin
        xyz="0.10385 0.072833 1.2754E-05"
        rpy="0 0 0" />
      <mass
        value="0.29494118" />
      <inertia
        ixx="0.00107176"
        ixy="-0.00134089"
        ixz="0.00000109"
        iyy="0.00185031"
        iyz="0.00000094"
        izz="0.00284949" />
    </inertial>
    <visual>
      <origin
        xyz="0 0 0"
        rpy="0 0 0" />
      <geometry>
        <mesh
          filename="file:///home/llq/leg_control/install/leg_model_1/share/leg_model_1/meshes/Knee_link.STL" />
      </geometry>
      <material
        name="">
        <color
          rgba="0.79216 0.81961 0.93333 1" />
      </material>
    </visual>
    <collision>
      <origin
        xyz="0 0 0"
        rpy="0 0 0" />
      <geometry>
        <mesh
          filename="file:///home/llq/leg_control/install/leg_model_1/share/leg_model_1/meshes/Knee_link.STL" />
      </geometry>
    </collision>
  </link>
  <joint
    name="Knee_joint"
    type="revolute">
    <origin
      xyz="-0.1391 -0.14371 -0.0913"
      rpy="3.1416 0 0" />
    <parent
      link="big_leg_Link" />
    <child
      link="Knee_link" />
    <axis
      xyz="0 0 -1" />
    <limit
      lower="-21"
      upper="21"
      effort="20"
      velocity="20" />
    <mimic
      joint="thigh_joint"
      multiplier="6.666667"
      offset="2" />
  </joint>
  <gazebo>
    <joint name="rod_to_knee_closed_loop" type="revolute">
      <parent>Rod_link</parent>
      <child>Knee_link</child>
      <pose>0 0 0 0 0 0</pose> 
      <axis>
        <xyz>0 0 1</xyz>
      </axis>
    </joint>

    <plugin name="gazebo_ros2_control" filename="libgazebo_ros2_control.so">
      <ros>
        <namespace>/</namespace>
      </ros>
      <robot_param>robot_description</robot_param>
      <robot_param_node>robot_description_server</robot_param_node>
      <parameters>package://leg_model_1/config/ros2_controllers.yaml</parameters>
    </plugin>
  </gazebo>

  <ros2_control name="LegModel1System" type="system">
    <hardware>
      <plugin>gazebo_ros2_control/GazeboSystem</plugin>
    </hardware>

    <joint name="hip_joint">
      <command_interface name="effort" />
      <state_interface name="position" />
      <state_interface name="velocity" />
      <state_interface name="effort" />
    </joint>

    <joint name="big_leg_joint">
      <command_interface name="effort" />
      <state_interface name="position" />
      <state_interface name="velocity" />
      <state_interface name="effort" />
    </joint>

    <joint name="thigh_joint">
      <command_interface name="effort" />
      <state_interface name="position" />
      <state_interface name="velocity" />
      <state_interface name="effort" />
    </joint>
  </ros2_control>
</robot>