<sdf version='1.7'>
  <model name='leg_model_1'>
    <link name='base_link'>
      <inertial>
        <pose>-0.000146 -0.004321 0.30277 0 -0 0</pose>
        <mass>10502.1</mass>
        <inertia>
          <ixx>1076.39</ixx>
          <ixy>0</ixy>
          <ixz>-0.02</ixz>
          <iyy>1072.16</iyy>
          <iyz>-0.08</iyz>
          <izz>44.67</izz>
        </inertia>
      </inertial>
      <collision name='base_link_collision'>
        <pose>0 0 0 0 -0 0</pose>
        <geometry>
          <mesh>
            <scale>1 1 1</scale>
            <uri>file:///home/llq/leg_control/install/leg_model_1/share/leg_model_1/meshes/base_link.STL</uri>
          </mesh>
        </geometry>
      </collision>
      <visual name='base_link_visual'>
        <pose>0 0 0 0 -0 0</pose>
        <geometry>
          <mesh>
            <scale>1 1 1</scale>
            <uri>file:///home/llq/leg_control/install/leg_model_1/share/leg_model_1/meshes/base_link.STL</uri>
          </mesh>
        </geometry>
      </visual>
    </link>
    <joint name='hip_joint' type='revolute'>
      <pose relative_to='base_link'>-0.000679 -0.06 0.41107 1.5708 -0 0</pose>
      <parent>base_link</parent>
      <child>hip_link</child>
      <axis>
        <xyz>0 0 1</xyz>
        <limit>
          <lower>3.13</lower>
          <upper>3.14</upper>
          <effort>20</effort>
          <velocity>20</velocity>
        </limit>
        <dynamics>
          <spring_reference>0</spring_reference>
          <spring_stiffness>0</spring_stiffness>
        </dynamics>
      </axis>
    </joint>
    <link name='hip_link'>
      <pose relative_to='hip_joint'>0 0 0 0 -0 0</pose>
      <inertial>
        <pose>-0.023835 0.000948 0.039743 0 -0 3.14159</pose>
        <mass>0.5276</mass>
        <inertia>
          <ixx>0.00036792</ixx>
          <ixy>1.39e-06</ixy>
          <ixz>3.833e-05</ixz>
          <iyy>0.00040268</iyy>
          <iyz>-1.56e-06</iyz>
          <izz>0.00034332</izz>
        </inertia>
      </inertial>
      <collision name='hip_link_collision'>
        <pose>0 0 0 0 -0 0</pose>
        <geometry>
          <mesh>
            <scale>1 1 1</scale>
            <uri>file:///home/llq/leg_control/install/leg_model_1/share/leg_model_1/meshes/hip_link.STL</uri>
          </mesh>
        </geometry>
      </collision>
      <visual name='hip_link_visual'>
        <pose>0 0 0 0 -0 3.14159</pose>
        <geometry>
          <mesh>
            <scale>1 1 1</scale>
            <uri>file:///home/llq/leg_control/install/leg_model_1/share/leg_model_1/meshes/hip_link.STL</uri>
          </mesh>
        </geometry>
      </visual>
    </link>
    <joint name='big_leg_joint' type='revolute'>
      <pose relative_to='hip_link'>0.005496 -0.000219 0.045 -0.039793 -1.57079 -3.14159</pose>
      <parent>hip_link</parent>
      <child>big_leg_Link</child>
      <axis>
        <xyz>0 0 1</xyz>
        <limit>
          <lower>-3.14</lower>
          <upper>3.14</upper>
          <effort>20</effort>
          <velocity>20</velocity>
        </limit>
        <dynamics>
          <spring_reference>0</spring_reference>
          <spring_stiffness>0</spring_stiffness>
        </dynamics>
      </axis>
    </joint>
    <link name='big_leg_Link'>
      <pose relative_to='big_leg_joint'>0 0 0 0 -0 0</pose>
      <inertial>
        <pose>-0.019809 -0.01644 -0.060094 0 -0 0</pose>
        <mass>0.75553</mass>
        <inertia>
          <ixx>0.00167856</ixx>
          <ixy>-0.00075514</ixy>
          <ixz>-0.00036372</ixz>
          <iyy>0.0018937</iyy>
          <iyz>0.00030137</iyz>
          <izz>0.00203925</izz>
        </inertia>
      </inertial>
      <collision name='big_leg_Link_collision'>
        <pose>0 0 0 0 -0 0</pose>
        <geometry>
          <mesh>
            <scale>1 1 1</scale>
            <uri>file:///home/llq/leg_control/install/leg_model_1/share/leg_model_1/meshes/big_leg_Link.STL</uri>
          </mesh>
        </geometry>
      </collision>
      <visual name='big_leg_Link_visual'>
        <pose>0 0 0 0 -0 0</pose>
        <geometry>
          <mesh>
            <scale>1 1 1</scale>
            <uri>file:///home/llq/leg_control/install/leg_model_1/share/leg_model_1/meshes/big_leg_Link.STL</uri>
          </mesh>
        </geometry>
      </visual>
    </link>
    <joint name='Knee_joint' type='revolute'>
      <pose relative_to='big_leg_Link'>-0.1391 -0.14371 -0.0913 -3.14159 0 0</pose>
      <parent>big_leg_Link</parent>
      <child>Knee_link</child>
      <axis>
        <xyz>0 0 -1</xyz>
        <limit>
          <lower>-3.14</lower>
          <upper>3.14</upper>
          <effort>20</effort>
          <velocity>20</velocity>
        </limit>
        <dynamics>
          <spring_reference>0</spring_reference>
          <spring_stiffness>0</spring_stiffness>
        </dynamics>
      </axis>
    </joint>
    <link name='Knee_link'>
      <pose relative_to='Knee_joint'>0 0 0 0 -0 0</pose>
      <inertial>
        <pose>0.10385 0.072833 1.3e-05 -3e-06 3e-06 3.14159</pose>
        <mass>0.294941</mass>
        <inertia>
          <ixx>0.00107176</ixx>
          <ixy>-0.00134089</ixy>
          <ixz>1.09e-06</ixz>
          <iyy>0.00185031</iyy>
          <iyz>9.4e-07</iyz>
          <izz>0.00284949</izz>
        </inertia>
      </inertial>
      <collision name='Knee_link_collision'>
        <pose>0 0 0 0 -0 0</pose>
        <geometry>
          <mesh>
            <scale>1 1 1</scale>
            <uri>file:///home/llq/leg_control/install/leg_model_1/share/leg_model_1/meshes/Knee_link.STL</uri>
          </mesh>
        </geometry>
      </collision>
      <visual name='Knee_link_visual'>
        <pose>0 0 0 -3e-06 3e-06 3.14159</pose>
        <geometry>
          <mesh>
            <scale>1 1 1</scale>
            <uri>file:///home/llq/leg_control/install/leg_model_1/share/leg_model_1/meshes/Knee_link.STL</uri>
          </mesh>
        </geometry>
      </visual>
    </link>
    <joint name='thigh_joint' type='revolute'>
      <pose relative_to='big_leg_Link'>0 0 -0.0823 3.14159 -0 0</pose>
      <parent>big_leg_Link</parent>
      <child>thigh_link</child>
      <axis>
        <xyz>0 0 1</xyz>
        <limit>
          <lower>-3.14</lower>
          <upper>3.14</upper>
          <effort>20</effort>
          <velocity>20</velocity>
        </limit>
        <dynamics>
          <spring_reference>0</spring_reference>
          <spring_stiffness>0</spring_stiffness>
        </dynamics>
      </axis>
    </joint>
    <link name='thigh_link'>
      <pose relative_to='thigh_joint'>0 0 0 0 -0 0</pose>
      <inertial>
        <pose>-0.003814 -0.004746 -0.002118 0 -0 0</pose>
        <mass>0.02498</mass>
        <inertia>
          <ixx>5.69e-06</ixx>
          <ixy>-2.62e-06</ixy>
          <ixz>1.32e-06</ixz>
          <iyy>4.53e-06</iyy>
          <iyz>1.65e-06</iyz>
          <izz>8.08e-06</izz>
        </inertia>
      </inertial>
      <collision name='thigh_link_collision'>
        <pose>0 0 0 0 -0 0</pose>
        <geometry>
          <mesh>
            <scale>1 1 1</scale>
            <uri>file:///home/llq/leg_control/install/leg_model_1/share/leg_model_1/meshes/thigh_link.STL</uri>
          </mesh>
        </geometry>
      </collision>
      <visual name='thigh_link_visual'>
        <pose>0 0 0 0 -0 0</pose>
        <geometry>
          <mesh>
            <scale>1 1 1</scale>
            <uri>file:///home/llq/leg_control/install/leg_model_1/share/leg_model_1/meshes/thigh_link.STL</uri>
          </mesh>
        </geometry>
      </visual>
    </link>
    <joint name='Rod_joint' type='revolute'>
      <pose relative_to='thigh_link'>-0.018796 -0.023382 0.0128 0 -0 0</pose>
      <parent>thigh_link</parent>
      <child>Rod_link</child>
      <axis>
        <xyz>0 0 1</xyz>
        <limit>
          <lower>-3.14</lower>
          <upper>3.14</upper>
          <effort>20</effort>
          <velocity>20</velocity>
        </limit>
        <dynamics>
          <spring_reference>0</spring_reference>
          <spring_stiffness>0</spring_stiffness>
        </dynamics>
      </axis>
    </joint>
    <link name='Rod_link'>
      <pose relative_to='Rod_joint'>0 0 0 0 -0 0</pose>
      <inertial>
        <pose>-0.068989 0.071266 -0.00382 0 -0 0</pose>
        <mass>0.03111</mass>
        <inertia>
          <ixx>6.403e-05</ixx>
          <ixy>6.126e-05</ixy>
          <ixz>4e-08</ixz>
          <iyy>6.001e-05</iyy>
          <iyz>-4e-08</iyz>
          <izz>0.00012343</izz>
        </inertia>
      </inertial>
      <collision name='Rod_link_collision'>
        <pose>0 0 0 0 -0 0</pose>
        <geometry>
          <mesh>
            <scale>1 1 1</scale>
            <uri>file:///home/llq/leg_control/install/leg_model_1/share/leg_model_1/meshes/Rod_link.STL</uri>
          </mesh>
        </geometry>
      </collision>
      <visual name='Rod_link_visual'>
        <pose>0 0 0 0 -0 0</pose>
        <geometry>
          <mesh>
            <scale>1 1 1</scale>
            <uri>file:///home/llq/leg_control/install/leg_model_1/share/leg_model_1/meshes/Rod_link.STL</uri>
          </mesh>
        </geometry>
      </visual>
    </link>
    <static>0</static>
    <joint name='rod_to_knee_closed_loop' type='revolute'>
      <parent>Rod_link</parent>
      <child>Knee_link</child>
      <pose relative_to='Rod_link'>-0.086 0.444 -0.083 0 0 0</pose>
      <axis>
        <xyz>0 0 1</xyz>
        <limit>
          <lower>-1e+16</lower>
          <upper>1e+16</upper>
        </limit>
      </axis>
    </joint>
    <plugin name='gazebo_ros2_control' filename='libgazebo_ros2_control.so'>
      <ros>
        <namespace>/</namespace>
      </ros>
      <robot_param>robot_description</robot_param>
      <robot_param_node>robot_description_server</robot_param_node>
      <parameters>package://leg_model_1/config/ros2_controllers.yaml</parameters>
    </plugin>
  </model>
</sdf>
