<?xml version="1.0"?>
<robot name="robot_arm">
  <link name="base_link">
      <visual>
        <origin xyz="0 0 0" rpy="0 0 0" />
        <geometry>
          <mesh filename="package://arm_model/model/base_link.STL" />
        </geometry>
        <material name="default">
          <color rgba="1.00000000 1.00000000 1.00000000 1.00000000"/>
        </material>
      </visual>
      <collision>
        <origin xyz="0 0 0.005" rpy="0 0 0" />
        <geometry>
          <cylinder radius="0.137364" length="0.000001" />
        </geometry>
      </collision>
      <inertial>
        <origin xyz="0 0 0.013347" rpy="0 0 0" />
        <mass value="0.31733" />
        <inertia ixx="0.0002426" ixy="0" ixz="0" iyy="0.0002426" iyz="0" izz="0.0004234" />
      </inertial>
    </link>
  <link name="base_yaw_Link">
      <visual>
        <origin xyz="0 0 0" rpy="0 0 0" />
        <geometry>
          <mesh filename="package://arm_model/model/base_yaw_Link.STL" />
        </geometry>
        <material name="default">
          <color rgba="1.00000000 1.00000000 1.00000000 1.00000000"/>
        </material>
      </visual>
      <collision>
        <origin xyz="-0.0010804 -0.0038333 0.034" rpy="0 0 0" />
        <geometry>
          <cylinder radius="0.010001" length="0.118469" />
        </geometry>
      </collision>
      <inertial>
        <origin xyz="-0.0020917 -0.0074065 0.032382" rpy="0 0 0" />
        <mass value="0.22637" />
        <inertia ixx="0.0001279" ixy="0.0000052" ixz="0.0000048" iyy="0.0001444" iyz="0.000018" izz="0.0001467" />
      </inertial>
    </link>
  <link name="upper_arm_link">
      <visual>
        <origin xyz="0 0 0" rpy="0 0 0" />
        <geometry>
          <mesh filename="package://arm_model/model/upper_arm_link.STL" />
        </geometry>
        <material name="default">
          <color rgba="1.00000000 1.00000000 1.00000000 1.00000000"/>
        </material>
      </visual>
      <collision>
        <origin xyz="-0.1009507 0.0165225 -0.0000248" rpy="-3.1328242 -0.0001984 -0.1367144" />
        <geometry>
          <box size="0.163662 0.024919 0.007327" />
        </geometry>
      </collision>
      <inertial>
        <origin xyz="-0.15294 0.02387 0" rpy="0 0 0" />
        <mass value="0.24808" />
        <inertia ixx="0.000124" ixy="0.0001414" ixz="0" iyy="0.0005979" iyz="0" izz="0.0006166" />
      </inertial>
    </link>
  <link name="forearm_link">
      <visual>
        <origin xyz="0 0 0" rpy="0 0 0" />
        <geometry>
          <mesh filename="package://arm_model/model/forearm_link.STL" />
        </geometry>
        <material name="default">
          <color rgba="1.00000000 1.00000000 1.00000000 1.00000000"/>
        </material>
      </visual>
      <collision>
        <origin xyz="0.0969654 -0.0145236 0.0444222" rpy="3.0486435 -0.2620476 -0.1375345" />
        <geometry>
          <box size="0.15 0.015238 0.012728" />
        </geometry>
      </collision>
      <inertial>
        <origin xyz="0.14778 -0.023186 0.050608" rpy="0 0 0" />
        <mass value="0.2587" />
        <inertia ixx="0.000185" ixy="0.0001548" ixz="-0.0001335" iyy="0.0007044" iyz="0.0000371" izz="0.0006698" />
      </inertial>
    </link>
  <link name="wrist_link">
      <visual>
        <origin xyz="0 0 0" rpy="0 0 0" />
        <geometry>
          <mesh filename="package://arm_model/model/wrist_link.STL" />
        </geometry>
        <material name="default">
          <color rgba="1.00000000 1.00000000 1.00000000 1.00000000"/>
        </material>
      </visual>
      <collision>
        <origin xyz="0.0201568 -0.0209135 -0.0095326" rpy="-1.4993451 0.3553112 -0.8455611" />
        <geometry>
          <box size="0.049957 0.017099 0.015769" />
        </geometry>
      </collision>
      <inertial>
        <origin xyz="0.020287 -0.022165 -0.010354" rpy="0 0 0" />
        <mass value="0.047454" />
        <inertia ixx="0.0000316" ixy="0.000014" ixz="0.0000076" iyy="0.0000313" iyz="-0.0000068" izz="0.0000417" />
      </inertial>
    </link>
  <link name="end_effector_fixed_joint">
      <visual>
        <origin xyz="0 0 0" rpy="0 0 0" />
        <geometry>
          <mesh filename="package://arm_model/model/end_effector_fixed_joint.STL" />
        </geometry>
        <material name="default">
          <color rgba="1.00000000 1.00000000 1.00000000 1.00000000"/>
        </material>
      </visual>
      <collision>
        <origin xyz="-0.0354207 0.0096738 -0.0080076" rpy="0.0064462 0.0665544 -0.271741" />
        <geometry>
          <box size="0.124232 0.070576 0.016323" />
        </geometry>
      </collision>
      <inertial>
        <origin xyz="-0.041409 0.011419 -0.017913" rpy="0 0 0" />
        <mass value="0.32249" />
        <inertia ixx="0.0007915" ixy="0.0000435" ixz="0.0000128" iyy="0.0009371" iyz="-0.0000035" izz="0.0016677" />
      </inertial>
    </link>
  <joint name="base_yaw_joint" type="revolute">
      <parent link="base_link" />
      <child link="base_yaw_Link" />
      <origin xyz="0.000017 -0.0000228 0.058" rpy="0 0 0" />
      <axis xyz="0 0 1" />
      <limit lower="-3.14" upper="3.14" effort="10" velocity="1" />
    </joint>
  <joint name="shoulder_pitch_joint" type="revolute">
      <parent link="base_yaw_Link" />
      <child link="upper_arm_link" />
      <origin xyz="0.0080913 0.029425 0.0395" rpy="0 0 0" />
      <axis xyz="0.26585 0.96402 0" />
      <limit lower="-0.42" upper="3.58" effort="10" velocity="1" />
    </joint>
  <joint name="elbow_pitch_joint" type="revolute">
      <parent link="upper_arm_link" />
      <child link="forearm_link" />
      <origin xyz="-0.21008 -0.0094917 0" rpy="0 0 0" />
      <axis xyz="-0.26585 -0.96402 0" />
      <limit lower="0" upper="3.14" effort="10" velocity="1" />
    </joint>
  <joint name="wrist_pitch_joint" type="revolute">
      <parent link="forearm_link" />
      <child link="wrist_link" />
      <origin xyz="0.21061 0.01142 0.057" rpy="0 0 0" />
      <axis xyz="0.26585 0.96402 0" />
      <limit lower="-3.14" upper="0.3" effort="10" velocity="1" />
    </joint>
  <joint name="end_effector_link" type="fixed">
      <parent link="wrist_link" />
      <child link="end_effector_fixed_joint" />
      <origin xyz="0.16309 -0.080763 -0.016359" rpy="0 0 0" />
    </joint>
</robot>