<?xml version="1.0" ?>
<!-- =================================================================================== -->
<!-- |    This document was autogenerated by xacro from /home/zhr/robot_arm/install/arm_bringup/share/arm_bringup/urdf/robot_arm.urdf | -->
<!-- |    EDITING THIS FILE BY HAND IS NOT RECOMMENDED                                 | -->
<!-- =================================================================================== -->
<robot name="robot_arm">
  <link name="world"/>
  <joint name="world_to_base_footprint" type="fixed">
    <parent link="world"/>
    <child link="base_footprint"/>
    <origin rpy="0 0 0" xyz="0 0 0"/>
  </joint>
  <link name="base_footprint"/>
  <joint name="base_footprint_joint" type="fixed">
    <parent link="base_footprint"/>
    <child link="base_link"/>
    <origin rpy="0 0 0" xyz="0 0 0"/>
  </joint>
  <link name="base_link">
    <inertial>
      <origin rpy="0 0 0" xyz="6.9777E-17 -2.4059E-18 0.013347"/>
      <mass value="0.31733"/>
      <inertia ixx="0.00024261" ixy="-2.7113E-20" ixz="-1.2948E-21" iyy="0.00024261" iyz="-3.7462E-22" izz="0.0004234"/>
    </inertial>
    <visual>
      <origin rpy="0 0 0" xyz="0 0 0"/>
      <geometry>
        <mesh filename="package://arm_bringup/meshes/base_link.STL"/>
      </geometry>
      <material name="">
        <color rgba="1 1 1 1"/>
      </material>
    </visual>
    <collision>
      <origin rpy="0 0 0" xyz="0 0 0"/>
      <geometry>
        <mesh filename="package://arm_bringup/meshes/base_link.STL"/>
      </geometry>
    </collision>
  </link>
  <link name="base_yaw_Link">
    <inertial>
      <origin rpy="0 0 0" xyz="-0.0020917 -0.0074065 0.032382"/>
      <mass value="0.22637"/>
      <inertia ixx="0.00012786" ixy="5.2428E-06" ixz="4.8448E-06" iyy="0.00014439" iyz="1.7959E-05" izz="0.00014668"/>
    </inertial>
    <visual>
      <origin rpy="0 0 0" xyz="0 0 0"/>
      <geometry>
        <mesh filename="package://arm_bringup/meshes/base_yaw_Link.STL"/>
      </geometry>
      <material name="">
        <color rgba="1 1 1 1"/>
      </material>
    </visual>
    <collision>
      <origin rpy="0 0 0" xyz="0 0 0"/>
      <geometry>
        <mesh filename="package://arm_bringup/meshes/base_yaw_Link.STL"/>
      </geometry>
    </collision>
  </link>
  <joint name="base_yaw_joint" type="revolute">
    <origin rpy="0 0 0" xyz="1.6999E-05 -2.2768E-05 0.058"/>
    <parent link="base_link"/>
    <child link="base_yaw_Link"/>
    <axis xyz="0 0 1"/>
    <limit effort="10" lower="-3.14" upper="3.14" velocity="1"/>
    <dynamics damping="0.2" friction="0.05"/>
  </joint>
  <link name="upper_arm_link">
    <inertial>
      <origin rpy="0 0 0" xyz="-0.15294 0.02387 3.1919E-16"/>
      <mass value="0.24808"/>
      <inertia ixx="0.00012398" ixy="0.00014142" ixz="-4.2389E-19" iyy="0.00059792" iyz="1.1275E-19" izz="0.00061661"/>
    </inertial>
    <visual>
      <origin rpy="0 0 0" xyz="0 0 0"/>
      <geometry>
        <mesh filename="package://arm_bringup/meshes/upper_arm_link.STL"/>
      </geometry>
      <material name="">
        <color rgba="1 1 1 1"/>
      </material>
    </visual>
    <collision>
      <origin rpy="0 0 0" xyz="0 0 0"/>
      <geometry>
        <mesh filename="package://arm_bringup/meshes/upper_arm_link.STL"/>
      </geometry>
    </collision>
  </link>
  <joint name="shoulder_pitch_joint" type="revolute">
    <origin rpy="0 0 0" xyz="0.0080913 0.029425 0.0395"/>
    <parent link="base_yaw_Link"/>
    <child link="upper_arm_link"/>
    <axis xyz="0.26585 0.96402 0"/>
    <limit effort="10" lower="-3.14" upper="3.14" velocity="1"/>
    <dynamics damping="0.8" friction="0.08"/>
  </joint>
  <link name="forearm_link">
    <inertial>
      <origin rpy="0 0 0" xyz="0.14778 -0.023186 0.050608"/>
      <mass value="0.2587"/>
      <inertia ixx="0.00018496" ixy="0.00015479" ixz="-0.00013355" iyy="0.0007044" iyz="3.7085E-05" izz="0.00066978"/>
    </inertial>
    <visual>
      <origin rpy="0 0 0" xyz="0 0 0"/>
      <geometry>
        <mesh filename="package://arm_bringup/meshes/forearm_link.STL"/>
      </geometry>
      <material name="">
        <color rgba="1 1 1 1"/>
      </material>
    </visual>
    <collision>
      <origin rpy="0 0 0" xyz="0 0 0"/>
      <geometry>
        <mesh filename="package://arm_bringup/meshes/forearm_link.STL"/>
      </geometry>
    </collision>
  </link>
  <joint name="elbow_pitch_joint" type="revolute">
    <origin rpy="0 0 0" xyz="-0.21008 -0.0094917 0"/>
    <parent link="upper_arm_link"/>
    <child link="forearm_link"/>
    <axis xyz="-0.26585 -0.96402 0"/>
    <limit effort="10" lower="-3.14" upper="3.14" velocity="1"/>
    <dynamics damping="0.7" friction="0.06"/>
  </joint>
  <link name="wrist_link">
    <inertial>
      <origin rpy="0 0 0" xyz="0.020287 -0.022165 -0.010354"/>
      <mass value="0.047454"/>
      <inertia ixx="3.1605E-05" ixy="1.4022E-05" ixz="7.6127E-06" iyy="3.1295E-05" iyz="-6.8135E-06" izz="4.173E-05"/>
    </inertial>
    <visual>
      <origin rpy="0 0 0" xyz="0 0 0"/>
      <geometry>
        <mesh filename="package://arm_bringup/meshes/wrist_link.STL"/>
      </geometry>
      <material name="">
        <color rgba="1 1 1 1"/>
      </material>
    </visual>
    <collision>
      <origin rpy="0 0 0" xyz="0 0 0"/>
      <geometry>
        <mesh filename="package://arm_bringup/meshes/wrist_link.STL"/>
      </geometry>
    </collision>
  </link>
  <joint name="wrist_pitch_joint" type="revolute">
    <origin rpy="0 0 0" xyz="0.21061 0.01142 0.057"/>
    <parent link="forearm_link"/>
    <child link="wrist_link"/>
    <axis xyz="0.26585 0.96402 0"/>
    <limit effort="10" lower="-3.14" upper="3.14" velocity="1"/>
    <dynamics damping="0.35" friction="0.04"/>
  </joint>
  <link name="end_effector_fixed_joint">
    <inertial>
      <origin rpy="0 0 0" xyz="-0.041409 0.011419 -0.017913"/>
      <mass value="0.32249"/>
      <inertia ixx="0.00079154" ixy="4.3451E-05" ixz="1.2755E-05" iyy="0.00093712" iyz="-3.5174E-06" izz="0.0016677"/>
    </inertial>
    <visual>
      <origin rpy="0 0 0" xyz="0 0 0"/>
      <geometry>
        <mesh filename="package://arm_bringup/meshes/end_effector_fixed_joint.STL"/>
      </geometry>
      <material name="">
        <color rgba="1 1 1 1"/>
      </material>
    </visual>
    <collision>
      <origin rpy="0 0 0" xyz="0 0 0"/>
      <geometry>
        <mesh filename="package://arm_bringup/meshes/end_effector_fixed_joint.STL"/>
      </geometry>
    </collision>
  </link>
  <joint name="end_effector_link" type="fixed">
    <origin rpy="0 0 0" xyz="0.16309 -0.080763 -0.016359"/>
    <parent link="wrist_link"/>
    <child link="end_effector_fixed_joint"/>
    <axis xyz="0 0 0"/>
  </joint>
  <ros2_control name="ArmGazeboSystem" type="system">
    <hardware>
      <plugin>gazebo_ros2_control/GazeboSystem</plugin>
    </hardware>
    <joint name="base_yaw_joint">
      <command_interface name="position"/>
      <state_interface name="position"/>
      <state_interface name="velocity"/>
      <state_interface name="effort"/>
    </joint>
    <joint name="shoulder_pitch_joint">
      <command_interface name="position"/>
      <state_interface name="position"/>
      <state_interface name="velocity"/>
      <state_interface name="effort"/>
    </joint>
    <joint name="elbow_pitch_joint">
      <command_interface name="position"/>
      <state_interface name="position"/>
      <state_interface name="velocity"/>
      <state_interface name="effort"/>
    </joint>
    <joint name="wrist_pitch_joint">
      <command_interface name="position"/>
      <state_interface name="position"/>
      <state_interface name="velocity"/>
      <state_interface name="effort"/>
    </joint>
  </ros2_control>
  <gazebo>
    <plugin filename="libgazebo_ros2_control.so" name="gazebo_ros2_control">
      <parameters>/home/zhr/robot_arm/install/sim_motor_controller/share/sim_motor_controller/config/sim_controllers.yaml</parameters>
    </plugin>
  </gazebo>
</robot>
